<?xml version="1.0" ?>

<robot name="mico">

  <link name="mico_link_base">
    <visual>
      <geometry>
        <mesh filename="kinova_graphics/base.obj"/>
      </geometry>
    </visual>
    <inertial>
      <mass value="0.46784"/>
      <origin rpy="0 0 0" xyz="0 0 0.1255"/>
      <inertia ixx="0.000951270861568" ixy="0" ixz="0" iyy="0.000951270861568" iyz="0" izz="0.000374272"/>
    </inertial>
  </link>

  <link name="mico_link_1">
    <visual>
      <geometry>
        <mesh filename="kinova_graphics/shoulder.obj"/>
      </geometry>
    </visual>
    <visual>
      <geometry>
        <mesh filename="kinova_graphics/ring_big.obj"/>
      </geometry>
    </visual>
    <inertial>
      <mass value="0.7477"/>
      <origin xyz="0 -0.002 -0.0605"/>
      <inertia ixx="0.00152031725204" ixy="0" ixz="0" iyy="0.00152031725204" iyz="0" izz="0.00059816"/>
    </inertial>
  </link>
  
  <joint name="mico_joint_1" type="revolute">
    <parent link="mico_link_base"/>
    <child link="mico_link_1"/>
    <axis xyz="0 0 1"/>
    <limit effort="2000" lower="-6.28318530718" upper="6.28318530718" velocity="1"/>
    <origin rpy="0 3.14159265359 0" xyz="0 0 0.15675"/>
    <dynamics damping="0.0" friction="0.0"/>
  </joint>

  <link name="mico_link_2">
    <visual>
      <geometry>
        <mesh filename="kinova_graphics/arm_mico.obj"/>
      </geometry>
    </visual>
    <visual>
      <geometry>
        <mesh filename="kinova_graphics/ring_big.obj"/>
      </geometry>
    </visual>
    <inertial>
      <mass value="0.85968"/>
      <origin xyz="0 -0.145  -0.0076"/>
      <inertia ixx="0.00467090931629" ixy="0" ixz="0" iyy="0.000386856" iyz="0" izz="0.00467090931629"/>
    </inertial>
  </link>

  <joint name="mico_joint_2" type="revolute">
    <parent link="mico_link_1"/>
    <child link="mico_link_2"/>
    <axis xyz="0 0 1"/>
    <limit effort="2000" lower="0.872664625997" upper="5.41052068118" velocity="1"/>
    <origin rpy="-1.57079632679 0 3.14159265359" xyz="0 0.0016 -0.11875"/>
    <dynamics damping="0.0" friction="0.0"/>
  </joint>

  <link name="mico_link_3">
    <visual>
      <geometry>
        <mesh filename="kinova_graphics/forearm_mico.obj"/>
      </geometry>
    </visual>
    <visual>
      <geometry>
        <mesh filename="kinova_graphics/ring_big.obj"/>
      </geometry>
    </visual>
    <inertial>
      <mass value="0.606"/>
      <origin xyz="0 0.0463 -0.0065"/>
      <inertia ixx="0.0003837984648" ixy="0" ixz="0" iyy="0.0001212" iyz="0" izz="0.0003837984648"/>
    </inertial>
  </link>

  <joint name="mico_joint_3" type="revolute">
    <parent link="mico_link_2"/>
    <child link="mico_link_3"/>
    <axis xyz="0 0 1"/>
    <limit effort="2000" lower="0.610865238198" upper="5.67232006898" velocity="1"/>
    <origin rpy="0 3.14159265359 0" xyz="0 -0.290 0"/>
    <dynamics damping="0.0" friction="0.0"/>
  </joint>

  <link name="mico_link_4">
    <visual>
      <geometry>
        <mesh filename="kinova_graphics/wrist.obj"/>
      </geometry>
    </visual>
    <visual>
      <geometry>
        <mesh filename="kinova_graphics/ring_small.obj"/>
      </geometry>
    </visual>
    <inertial>
      <mass value="0.426367"/>
      <origin xyz="0 -0.037 -0.0642"/>
      <inertia ixx="7.73496906e-05" ixy="0" ixz="0" iyy="7.73496906e-05" iyz="0" izz="0.0001428"/>
    </inertial>
  </link>

  <joint name="mico_joint_4" type="revolute">
    <parent link="mico_link_3"/>
    <child link="mico_link_4"/>
    <axis xyz="0 0 1"/>
    <limit effort="2000" lower="-6.28318530718" upper="6.28318530718" velocity="1"/>
    <origin rpy="-1.57079632679 0 3.14159265359" xyz="0 0.1231 -0.0086"/>
    <dynamics damping="0.0" friction="0.0"/>
  </joint>

  <link name="mico_link_5">
    <visual>
      <geometry>
        <mesh filename="kinova_graphics/wrist.obj"/>
      </geometry>
    </visual>
    <visual>
      <geometry>
        <mesh filename="kinova_graphics/ring_small.obj"/>
      </geometry>
    </visual>
    <inertial>
      <mass value="0.426367"/>
      <origin xyz="0 -0.037 -0.0642"/>
      <inertia ixx="7.73496906e-05" ixy="0" ixz="0" iyy="7.73496906e-05" iyz="0" izz="0.0001428"/>
    </inertial>
  </link>

  <joint name="mico_joint_5" type="revolute">
    <parent link="mico_link_4"/>
    <child link="mico_link_5"/>
    <axis xyz="0 0 1"/>
    <limit effort="2000" lower="-6.28318530718" upper="6.28318530718" velocity="1"/>
    <origin rpy="1.0471975512 0 3.14159265359" xyz="0 -0.03703 -0.06414"/>
    <dynamics damping="0.0" friction="0.0"/>
  </joint>

  <link name="mico_link_6">
    <visual>
      <geometry>
        <mesh filename="kinova_graphics/hand_2finger.obj"/>
      </geometry>
    </visual>
    <visual>
      <geometry>
        <mesh filename="kinova_graphics/ring_small.obj"/>
      </geometry>
    </visual>
    <inertial>
      <mass value="0.78"/>
      <origin xyz="0 0 -0.06"/>
      <inertia ixx="0.000370498518" ixy="0" ixz="0" iyy="0.000370498518" iyz="0" izz="0.000624"/>
    </inertial>
  </link>

  <joint name="mico_joint_6" type="revolute">
    <parent link="mico_link_5"/>
    <child link="mico_link_6"/>
    <axis xyz="0 0 1"/>
    <limit effort="2000" lower="-6.28318530718" upper="6.28318530718" velocity="1"/>
    <origin rpy="1.0471975512 0 3.14159265359" xyz="0 -0.03703 -0.06414"/>
    <dynamics damping="0.0" friction="0.0"/>
  </joint>

  <link name="mico_link_finger_1">
    <visual>
      <geometry>
        <mesh filename="kinova_graphics/finger_proximal.obj"/>
      </geometry>
    </visual>
    <inertial>
      <mass value="0.01"/>
      <origin xyz="0.022 0 0"/>
      <inertia ixx="7.8999684e-07" ixy="0" ixz="0" iyy="7.8999684e-07" iyz="0" izz="8e-08"/>
    </inertial>
  </link>

  <joint name="mico_joint_finger_1" type="fixed">
    <parent link="mico_link_6"/>
    <child link="mico_link_finger_1"/>
    <axis xyz="0 0 1"/>
    <origin rpy="-1.570796327 .649262481663582 1.57079632679490" xyz="-0.0025 0.03095 -0.11482"/>
    <limit effort="2000" lower="0" upper="2" velocity="1"/>
  </joint>

  <link name="mico_link_finger_tip_1">
    <visual>
      <geometry>
        <mesh filename="kinova_graphics/finger_distal.obj"/>
      </geometry>
    </visual>
    <inertial>
      <mass value="0.01"/>
      <origin xyz="0.022 0 0"/>
      <inertia ixx="7.8999684e-07" ixy="0" ixz="0" iyy="7.8999684e-07" iyz="0" izz="8e-08"/>
    </inertial>
  </link>

  <joint name="mico_joint_finger_tip_1" type="fixed">
    <parent link="mico_link_finger_1"/>
    <child link="mico_link_finger_tip_1"/>
    <axis xyz="0 0 1"/>
    <origin rpy="0 0 0" xyz="0.044 -0.003 0"/>
    <limit effort="2000" lower="0" upper="2" velocity="1"/>
  </joint>

  <link name="mico_link_finger_2">
    <visual>
      <geometry>
        <mesh filename="kinova_graphics/finger_proximal.obj"/>
      </geometry>
    </visual>
    <inertial>
      <mass value="0.01"/>
      <origin xyz="0.022 0 0"/>
      <inertia ixx="7.8999684e-07" ixy="0" ixz="0" iyy="7.8999684e-07" iyz="0" izz="8e-08"/>
    </inertial>
  </link>

  <joint name="mico_joint_finger_2" type="fixed">
    <parent link="mico_link_6"/>
    <child link="mico_link_finger_2"/>
    <axis xyz="0 0 1"/>
    <origin rpy="-1.570796327 .649262481663582 -1.57079632679490" xyz="-0.0025 -0.03095 -0.11482"/>
    <limit effort="2000" lower="0" upper="2" velocity="1"/>
  </joint>

  <link name="mico_link_finger_tip_2">
    <visual>
      <geometry>
        <mesh filename="kinova_graphics/finger_distal.obj"/>
      </geometry>
    </visual>
    <inertial>
      <mass value="0.01"/>
      <origin xyz="0.022 0 0"/>
      <inertia ixx="7.8999684e-07" ixy="0" ixz="0" iyy="7.8999684e-07" iyz="0" izz="8e-08"/>
    </inertial>
  </link>

  <joint name="mico_joint_finger_tip_2" type="fixed">
    <parent link="mico_link_finger_2"/>
    <child link="mico_link_finger_tip_2"/>
    <axis xyz="0 0 1"/>
    <origin rpy="0 0 0" xyz="0.044 -0.003 0"/>
    <limit effort="2000" lower="0" upper="2" velocity="1"/>
  </joint>
</robot>
